Traceback (most recent call last):
  File "C:\Users\lenovo\AppData\Local\Programs\Python\Python311\Lib\site-packages\jupyter_cache\executors\utils.py", line 58, in single_nb_execution
    executenb(
  File "C:\Users\lenovo\AppData\Local\Programs\Python\Python311\Lib\site-packages\nbclient\client.py", line 1305, in execute
    return NotebookClient(nb=nb, resources=resources, km=km, **kwargs).execute()
           ^^^^^^^^^^^^^^^^^^^^^^^^^^^^^^^^^^^^^^^^^^^^^^^^^^^^^^^^^^^^^^^^^^^^^
  File "C:\Users\lenovo\AppData\Roaming\Python\Python311\site-packages\jupyter_core\utils\__init__.py", line 166, in wrapped
    return loop.run_until_complete(inner)
           ^^^^^^^^^^^^^^^^^^^^^^^^^^^^^^
  File "C:\Users\lenovo\AppData\Local\Programs\Python\Python311\Lib\asyncio\base_events.py", line 653, in run_until_complete
    return future.result()
           ^^^^^^^^^^^^^^^
  File "C:\Users\lenovo\AppData\Local\Programs\Python\Python311\Lib\contextlib.py", line 222, in __aexit__
    await self.gen.athrow(typ, value, traceback)
  File "C:\Users\lenovo\AppData\Local\Programs\Python\Python311\Lib\site-packages\nbclient\client.py", line 650, in async_setup_kernel
    yield
  File "C:\Users\lenovo\AppData\Local\Programs\Python\Python311\Lib\site-packages\nbclient\client.py", line 705, in async_execute
    await self.async_execute_cell(
  File "C:\Users\lenovo\AppData\Local\Programs\Python\Python311\Lib\site-packages\nbclient\client.py", line 1058, in async_execute_cell
    await self._check_raise_for_error(cell, cell_index, exec_reply)
  File "C:\Users\lenovo\AppData\Local\Programs\Python\Python311\Lib\site-packages\nbclient\client.py", line 914, in _check_raise_for_error
    raise CellExecutionError.from_cell_and_msg(cell, exec_reply_content)
nbclient.exceptions.CellExecutionError: An error occurred while executing the following cell:
------------------
import numpy as np
import matplotlib.pyplot as plt
import statsmodels.api as sm
import pandas as pd

# Load the dataset
url = 'https://raw.githubusercontent.com/jbrownlee/Datasets/master/airline-passengers.csv'
df = pd.read_csv(url, header=0, index_col=0, parse_dates=True)

# Extract the passenger counts as the data
data = df['Passengers']

# Fit an AR(2) model
order = 2
model = sm.tsa.AutoReg(data, lags=order, trend='n').fit()

# Make predictions
predictions = model.predict(start=order, end=len(data)-1)

# Set font size
plt.rcParams.update({'font.size': 9})

# Plot the original and predicted time series
plt.figure(figsize=(8, 4))
plt.plot(data.index, data, label='Original Data')
plt.plot(data.index[order:], predictions, label=f'AR({order}) Predictions', linestyle='--')
plt.legend()
plt.xlabel('Time')
plt.ylabel('Passenger Count')
plt.title(f'AR({order}) Model')
plt.grid(True)

plt.show()

------------------


[1;31m---------------------------------------------------------------------------[0m
[1;31mModuleNotFoundError[0m                       Traceback (most recent call last)
Cell [1;32mIn[1], line 3[0m
[0;32m      1[0m [38;5;28;01mimport[39;00m [38;5;21;01mnumpy[39;00m [38;5;28;01mas[39;00m [38;5;21;01mnp[39;00m
[0;32m      2[0m [38;5;28;01mimport[39;00m [38;5;21;01mmatplotlib[39;00m[38;5;21;01m.[39;00m[38;5;21;01mpyplot[39;00m [38;5;28;01mas[39;00m [38;5;21;01mplt[39;00m
[1;32m----> 3[0m [38;5;28;01mimport[39;00m [38;5;21;01mstatsmodels[39;00m[38;5;21;01m.[39;00m[38;5;21;01mapi[39;00m [38;5;28;01mas[39;00m [38;5;21;01msm[39;00m
[0;32m      4[0m [38;5;28;01mimport[39;00m [38;5;21;01mpandas[39;00m [38;5;28;01mas[39;00m [38;5;21;01mpd[39;00m
[0;32m      6[0m [38;5;66;03m# Load the dataset[39;00m

[1;31mModuleNotFoundError[0m: No module named 'statsmodels'

