Traceback (most recent call last):
  File "C:\Users\lenovo\AppData\Local\Programs\Python\Python311\Lib\site-packages\jupyter_cache\executors\utils.py", line 58, in single_nb_execution
    executenb(
  File "C:\Users\lenovo\AppData\Local\Programs\Python\Python311\Lib\site-packages\nbclient\client.py", line 1305, in execute
    return NotebookClient(nb=nb, resources=resources, km=km, **kwargs).execute()
           ^^^^^^^^^^^^^^^^^^^^^^^^^^^^^^^^^^^^^^^^^^^^^^^^^^^^^^^^^^^^^^^^^^^^^
  File "C:\Users\lenovo\AppData\Roaming\Python\Python311\site-packages\jupyter_core\utils\__init__.py", line 166, in wrapped
    return loop.run_until_complete(inner)
           ^^^^^^^^^^^^^^^^^^^^^^^^^^^^^^
  File "C:\Users\lenovo\AppData\Local\Programs\Python\Python311\Lib\asyncio\base_events.py", line 653, in run_until_complete
    return future.result()
           ^^^^^^^^^^^^^^^
  File "C:\Users\lenovo\AppData\Local\Programs\Python\Python311\Lib\contextlib.py", line 222, in __aexit__
    await self.gen.athrow(typ, value, traceback)
  File "C:\Users\lenovo\AppData\Local\Programs\Python\Python311\Lib\site-packages\nbclient\client.py", line 650, in async_setup_kernel
    yield
  File "C:\Users\lenovo\AppData\Local\Programs\Python\Python311\Lib\site-packages\nbclient\client.py", line 705, in async_execute
    await self.async_execute_cell(
  File "C:\Users\lenovo\AppData\Local\Programs\Python\Python311\Lib\site-packages\nbclient\client.py", line 1058, in async_execute_cell
    await self._check_raise_for_error(cell, cell_index, exec_reply)
  File "C:\Users\lenovo\AppData\Local\Programs\Python\Python311\Lib\site-packages\nbclient\client.py", line 914, in _check_raise_for_error
    raise CellExecutionError.from_cell_and_msg(cell, exec_reply_content)
nbclient.exceptions.CellExecutionError: An error occurred while executing the following cell:
------------------
from statsmodels.stats.diagnostic import *

log_transformed = np.log(vals)
_, p = kstest_normal(log_transformed)  # stats.normaltest
print(f"significance: {p:.2f}")


------------------


[1;31m---------------------------------------------------------------------------[0m
[1;31mModuleNotFoundError[0m                       Traceback (most recent call last)
Cell [1;32mIn[12], line 1[0m
[1;32m----> 1[0m [38;5;28;01mfrom[39;00m [38;5;21;01mstatsmodels[39;00m[38;5;21;01m.[39;00m[38;5;21;01mstats[39;00m[38;5;21;01m.[39;00m[38;5;21;01mdiagnostic[39;00m [38;5;28;01mimport[39;00m [38;5;241m*[39m
[0;32m      3[0m log_transformed [38;5;241m=[39m np[38;5;241m.[39mlog(vals)
[0;32m      4[0m _, p [38;5;241m=[39m kstest_normal(log_transformed)  [38;5;66;03m# stats.normaltest[39;00m

[1;31mModuleNotFoundError[0m: No module named 'statsmodels'

